{
 "cells": [
  {
   "cell_type": "markdown",
   "id": "a45e03eb",
   "metadata": {},
   "source": [
    "## Listing 7.1 Functional API implementation of a two-input question-answering model\n"
   ]
  },
  {
   "cell_type": "code",
   "execution_count": 2,
   "id": "1decac34",
   "metadata": {},
   "outputs": [],
   "source": [
    "from keras import Model, layers, Input\n",
    "text_vocabulary_size = 10000\n",
    "question_vocabulary_size = 10000\n",
    "answer_vocabulary_size = 500"
   ]
  },
  {
   "cell_type": "code",
   "execution_count": 4,
   "id": "7c43474f",
   "metadata": {},
   "outputs": [],
   "source": [
    "# The text input is a variable\n",
    "# length sequence of integers.\n",
    "#  Note that you can optionally\n",
    "#  name the inputs.\n",
    "\n",
    "text_input = Input(shape=(None,), dtype='int32', name='text')\n"
   ]
  },
  {
   "cell_type": "code",
   "execution_count": 5,
   "id": "ee6e42ed",
   "metadata": {},
   "outputs": [],
   "source": [
    "embedded_text = layers.Embedding(64, text_vocabulary_size)(text_input)\n",
    "#  Embeds the inputs \n",
    "# into a sequence of \n",
    "# vectors of size 64"
   ]
  },
  {
   "cell_type": "code",
   "execution_count": 6,
   "id": "e23d0b1a",
   "metadata": {},
   "outputs": [],
   "source": [
    "# Encodes the vectors in a \n",
    "# single vector via an LSTM\n",
    "encoded_text = layers.LSTM(32)(embedded_text)\n"
   ]
  },
  {
   "cell_type": "code",
   "execution_count": 7,
   "id": "4e03c029",
   "metadata": {},
   "outputs": [],
   "source": [
    "# Same process (with different layer \n",
    "# instances) for the question\n",
    "question_input = Input(shape=(None,),dtype='int32',name='question')"
   ]
  },
  {
   "cell_type": "code",
   "execution_count": 8,
   "id": "e6f49a00",
   "metadata": {},
   "outputs": [],
   "source": [
    "embedded_question = layers.Embedding(32, question_vocabulary_size)(question_input)\n",
    "encoded_question = layers.LSTM(16)(embedded_question)"
   ]
  },
  {
   "cell_type": "code",
   "execution_count": 10,
   "id": "457c4bd8",
   "metadata": {},
   "outputs": [],
   "source": [
    "concatenated = layers.concatenate([encoded_text, encoded_question],\n",
    "axis=-1)"
   ]
  },
  {
   "cell_type": "code",
   "execution_count": 11,
   "id": "8c9a37fe",
   "metadata": {},
   "outputs": [],
   "source": [
    "# Adds a softmax \n",
    "# classifier on top\n",
    "answer = layers.Dense(answer_vocabulary_size,\n",
    "activation='softmax')(concatenated)"
   ]
  },
  {
   "cell_type": "code",
   "execution_count": 12,
   "id": "a4e67310",
   "metadata": {},
   "outputs": [],
   "source": [
    "# At model instantiation, you specify \n",
    "# the two inputs and the output.\n",
    "\n",
    "model = Model([text_input, question_input], answer)\n",
    "model.compile(optimizer='rmsprop',\n",
    "loss='categorical_crossentropy',\n",
    "metrics=['acc'])"
   ]
  },
  {
   "cell_type": "markdown",
   "id": "29b4d283",
   "metadata": {},
   "source": [
    "## Listing 7.2 Feeding data to a multi-input model"
   ]
  },
  {
   "cell_type": "code",
   "execution_count": 14,
   "id": "489ea377",
   "metadata": {},
   "outputs": [],
   "source": [
    "import numpy as np\n",
    "num_samples = 1000\n",
    "max_length = 100"
   ]
  },
  {
   "cell_type": "code",
   "execution_count": 46,
   "id": "fb2fad57",
   "metadata": {},
   "outputs": [],
   "source": [
    "text = np.random.randint(1, text_vocabulary_size,\n",
    "size=(num_samples, max_length))"
   ]
  },
  {
   "cell_type": "code",
   "execution_count": 47,
   "id": "b5582447",
   "metadata": {},
   "outputs": [
    {
     "data": {
      "text/plain": [
       "array([[5349,  780, 9315, 5736, 4749, 6497, 9634, 8169, 1987, 9706, 3957,\n",
       "        1396, 9653, 7110, 2500, 8307, 9089, 8146, 7109, 5175, 9947, 8159,\n",
       "         187, 4581, 7202, 9909, 8909,  809, 3885, 6208, 3712, 2853, 2450,\n",
       "        5607, 5213, 5296, 1293, 5484, 4690, 7109, 6330,  142, 8192, 7763,\n",
       "        7762,  998,  274, 8780, 6820, 9470, 8599, 5040, 5544, 1470, 8566,\n",
       "        6903, 1275, 3941, 1428, 2879, 9498, 6481, 3377, 2881, 8202, 8750,\n",
       "        7225, 2928, 2063,  615, 9898, 7953, 6888,  350, 7994, 3867, 1377,\n",
       "        8913,  632, 8138, 8112, 7566, 9905, 9206, 3390, 8333, 5138, 7277,\n",
       "        9292, 3000, 3136,  822, 7023,  566, 7629, 3915, 2156, 3913, 1576,\n",
       "        9565]])"
      ]
     },
     "execution_count": 47,
     "metadata": {},
     "output_type": "execute_result"
    }
   ],
   "source": [
    "text[[0]]"
   ]
  },
  {
   "cell_type": "code",
   "execution_count": 48,
   "id": "7a742744",
   "metadata": {},
   "outputs": [],
   "source": [
    "question = np.random.randint(1, question_vocabulary_size,\n",
    "size=(num_samples, max_length))"
   ]
  },
  {
   "cell_type": "code",
   "execution_count": 49,
   "id": "38460f67",
   "metadata": {},
   "outputs": [],
   "source": [
    "answers = np.random.randint(0, 1,\n",
    "size=(num_samples, answer_vocabulary_size))"
   ]
  },
  {
   "cell_type": "code",
   "execution_count": 50,
   "id": "fbc7c861",
   "metadata": {},
   "outputs": [
    {
     "name": "stdout",
     "output_type": "stream",
     "text": [
      "Epoch 1/2\n"
     ]
    },
    {
     "ename": "InvalidArgumentError",
     "evalue": "Graph execution error:\n\nDetected at node 'model/embedding/embedding_lookup' defined at (most recent call last):\n    File \"C:\\Users\\HP\\anaconda3\\lib\\runpy.py\", line 197, in _run_module_as_main\n      return _run_code(code, main_globals, None,\n    File \"C:\\Users\\HP\\anaconda3\\lib\\runpy.py\", line 87, in _run_code\n      exec(code, run_globals)\n    File \"C:\\Users\\HP\\anaconda3\\lib\\site-packages\\ipykernel_launcher.py\", line 16, in <module>\n      app.launch_new_instance()\n    File \"C:\\Users\\HP\\anaconda3\\lib\\site-packages\\traitlets\\config\\application.py\", line 846, in launch_instance\n      app.start()\n    File \"C:\\Users\\HP\\anaconda3\\lib\\site-packages\\ipykernel\\kernelapp.py\", line 677, in start\n      self.io_loop.start()\n    File \"C:\\Users\\HP\\anaconda3\\lib\\site-packages\\tornado\\platform\\asyncio.py\", line 199, in start\n      self.asyncio_loop.run_forever()\n    File \"C:\\Users\\HP\\anaconda3\\lib\\asyncio\\base_events.py\", line 596, in run_forever\n      self._run_once()\n    File \"C:\\Users\\HP\\anaconda3\\lib\\asyncio\\base_events.py\", line 1890, in _run_once\n      handle._run()\n    File \"C:\\Users\\HP\\anaconda3\\lib\\asyncio\\events.py\", line 80, in _run\n      self._context.run(self._callback, *self._args)\n    File \"C:\\Users\\HP\\anaconda3\\lib\\site-packages\\ipykernel\\kernelbase.py\", line 457, in dispatch_queue\n      await self.process_one()\n    File \"C:\\Users\\HP\\anaconda3\\lib\\site-packages\\ipykernel\\kernelbase.py\", line 446, in process_one\n      await dispatch(*args)\n    File \"C:\\Users\\HP\\anaconda3\\lib\\site-packages\\ipykernel\\kernelbase.py\", line 353, in dispatch_shell\n      await result\n    File \"C:\\Users\\HP\\anaconda3\\lib\\site-packages\\ipykernel\\kernelbase.py\", line 648, in execute_request\n      reply_content = await reply_content\n    File \"C:\\Users\\HP\\anaconda3\\lib\\site-packages\\ipykernel\\ipkernel.py\", line 353, in do_execute\n      res = shell.run_cell(code, store_history=store_history, silent=silent)\n    File \"C:\\Users\\HP\\anaconda3\\lib\\site-packages\\ipykernel\\zmqshell.py\", line 533, in run_cell\n      return super(ZMQInteractiveShell, self).run_cell(*args, **kwargs)\n    File \"C:\\Users\\HP\\anaconda3\\lib\\site-packages\\IPython\\core\\interactiveshell.py\", line 2901, in run_cell\n      result = self._run_cell(\n    File \"C:\\Users\\HP\\anaconda3\\lib\\site-packages\\IPython\\core\\interactiveshell.py\", line 2947, in _run_cell\n      return runner(coro)\n    File \"C:\\Users\\HP\\anaconda3\\lib\\site-packages\\IPython\\core\\async_helpers.py\", line 68, in _pseudo_sync_runner\n      coro.send(None)\n    File \"C:\\Users\\HP\\anaconda3\\lib\\site-packages\\IPython\\core\\interactiveshell.py\", line 3172, in run_cell_async\n      has_raised = await self.run_ast_nodes(code_ast.body, cell_name,\n    File \"C:\\Users\\HP\\anaconda3\\lib\\site-packages\\IPython\\core\\interactiveshell.py\", line 3364, in run_ast_nodes\n      if (await self.run_code(code, result,  async_=asy)):\n    File \"C:\\Users\\HP\\anaconda3\\lib\\site-packages\\IPython\\core\\interactiveshell.py\", line 3444, in run_code\n      exec(code_obj, self.user_global_ns, self.user_ns)\n    File \"C:\\Users\\HP\\AppData\\Local\\Temp/ipykernel_1284/4157008573.py\", line 1, in <module>\n      model.fit([text, question], answers, epochs=10, batch_size=128)\n    File \"C:\\Users\\HP\\anaconda3\\lib\\site-packages\\keras\\utils\\traceback_utils.py\", line 65, in error_handler\n      return fn(*args, **kwargs)\n    File \"C:\\Users\\HP\\anaconda3\\lib\\site-packages\\keras\\engine\\training.py\", line 1685, in fit\n      tmp_logs = self.train_function(iterator)\n    File \"C:\\Users\\HP\\anaconda3\\lib\\site-packages\\keras\\engine\\training.py\", line 1284, in train_function\n      return step_function(self, iterator)\n    File \"C:\\Users\\HP\\anaconda3\\lib\\site-packages\\keras\\engine\\training.py\", line 1268, in step_function\n      outputs = model.distribute_strategy.run(run_step, args=(data,))\n    File \"C:\\Users\\HP\\anaconda3\\lib\\site-packages\\keras\\engine\\training.py\", line 1249, in run_step\n      outputs = model.train_step(data)\n    File \"C:\\Users\\HP\\anaconda3\\lib\\site-packages\\keras\\engine\\training.py\", line 1050, in train_step\n      y_pred = self(x, training=True)\n    File \"C:\\Users\\HP\\anaconda3\\lib\\site-packages\\keras\\utils\\traceback_utils.py\", line 65, in error_handler\n      return fn(*args, **kwargs)\n    File \"C:\\Users\\HP\\anaconda3\\lib\\site-packages\\keras\\engine\\training.py\", line 558, in __call__\n      return super().__call__(*args, **kwargs)\n    File \"C:\\Users\\HP\\anaconda3\\lib\\site-packages\\keras\\utils\\traceback_utils.py\", line 65, in error_handler\n      return fn(*args, **kwargs)\n    File \"C:\\Users\\HP\\anaconda3\\lib\\site-packages\\keras\\engine\\base_layer.py\", line 1145, in __call__\n      outputs = call_fn(inputs, *args, **kwargs)\n    File \"C:\\Users\\HP\\anaconda3\\lib\\site-packages\\keras\\utils\\traceback_utils.py\", line 96, in error_handler\n      return fn(*args, **kwargs)\n    File \"C:\\Users\\HP\\anaconda3\\lib\\site-packages\\keras\\engine\\functional.py\", line 512, in call\n      return self._run_internal_graph(inputs, training=training, mask=mask)\n    File \"C:\\Users\\HP\\anaconda3\\lib\\site-packages\\keras\\engine\\functional.py\", line 669, in _run_internal_graph\n      outputs = node.layer(*args, **kwargs)\n    File \"C:\\Users\\HP\\anaconda3\\lib\\site-packages\\keras\\utils\\traceback_utils.py\", line 65, in error_handler\n      return fn(*args, **kwargs)\n    File \"C:\\Users\\HP\\anaconda3\\lib\\site-packages\\keras\\engine\\base_layer.py\", line 1145, in __call__\n      outputs = call_fn(inputs, *args, **kwargs)\n    File \"C:\\Users\\HP\\anaconda3\\lib\\site-packages\\keras\\utils\\traceback_utils.py\", line 96, in error_handler\n      return fn(*args, **kwargs)\n    File \"C:\\Users\\HP\\anaconda3\\lib\\site-packages\\keras\\layers\\core\\embedding.py\", line 272, in call\n      out = tf.nn.embedding_lookup(self.embeddings, inputs)\nNode: 'model/embedding/embedding_lookup'\nindices[120,0] = 5387 is not in [0, 64)\n\t [[{{node model/embedding/embedding_lookup}}]] [Op:__inference_train_function_5823]",
     "output_type": "error",
     "traceback": [
      "\u001b[1;31m---------------------------------------------------------------------------\u001b[0m",
      "\u001b[1;31mInvalidArgumentError\u001b[0m                      Traceback (most recent call last)",
      "\u001b[1;32m~\\AppData\\Local\\Temp/ipykernel_1284/3023182321.py\u001b[0m in \u001b[0;36m<module>\u001b[1;34m\u001b[0m\n\u001b[1;32m----> 1\u001b[1;33m \u001b[0mmodel\u001b[0m\u001b[1;33m.\u001b[0m\u001b[0mfit\u001b[0m\u001b[1;33m(\u001b[0m\u001b[1;33m[\u001b[0m\u001b[0mtext\u001b[0m\u001b[1;33m,\u001b[0m \u001b[0mquestion\u001b[0m\u001b[1;33m]\u001b[0m\u001b[1;33m,\u001b[0m \u001b[0manswers\u001b[0m\u001b[1;33m,\u001b[0m \u001b[0mepochs\u001b[0m\u001b[1;33m=\u001b[0m\u001b[1;36m2\u001b[0m\u001b[1;33m,\u001b[0m \u001b[0mbatch_size\u001b[0m\u001b[1;33m=\u001b[0m\u001b[1;36m128\u001b[0m\u001b[1;33m)\u001b[0m\u001b[1;33m\u001b[0m\u001b[1;33m\u001b[0m\u001b[0m\n\u001b[0m",
      "\u001b[1;32m~\\anaconda3\\lib\\site-packages\\keras\\utils\\traceback_utils.py\u001b[0m in \u001b[0;36merror_handler\u001b[1;34m(*args, **kwargs)\u001b[0m\n\u001b[0;32m     68\u001b[0m             \u001b[1;31m# To get the full stack trace, call:\u001b[0m\u001b[1;33m\u001b[0m\u001b[1;33m\u001b[0m\u001b[0m\n\u001b[0;32m     69\u001b[0m             \u001b[1;31m# `tf.debugging.disable_traceback_filtering()`\u001b[0m\u001b[1;33m\u001b[0m\u001b[1;33m\u001b[0m\u001b[0m\n\u001b[1;32m---> 70\u001b[1;33m             \u001b[1;32mraise\u001b[0m \u001b[0me\u001b[0m\u001b[1;33m.\u001b[0m\u001b[0mwith_traceback\u001b[0m\u001b[1;33m(\u001b[0m\u001b[0mfiltered_tb\u001b[0m\u001b[1;33m)\u001b[0m \u001b[1;32mfrom\u001b[0m \u001b[1;32mNone\u001b[0m\u001b[1;33m\u001b[0m\u001b[1;33m\u001b[0m\u001b[0m\n\u001b[0m\u001b[0;32m     71\u001b[0m         \u001b[1;32mfinally\u001b[0m\u001b[1;33m:\u001b[0m\u001b[1;33m\u001b[0m\u001b[1;33m\u001b[0m\u001b[0m\n\u001b[0;32m     72\u001b[0m             \u001b[1;32mdel\u001b[0m \u001b[0mfiltered_tb\u001b[0m\u001b[1;33m\u001b[0m\u001b[1;33m\u001b[0m\u001b[0m\n",
      "\u001b[1;32m~\\anaconda3\\lib\\site-packages\\tensorflow\\python\\eager\\execute.py\u001b[0m in \u001b[0;36mquick_execute\u001b[1;34m(op_name, num_outputs, inputs, attrs, ctx, name)\u001b[0m\n\u001b[0;32m     50\u001b[0m   \u001b[1;32mtry\u001b[0m\u001b[1;33m:\u001b[0m\u001b[1;33m\u001b[0m\u001b[1;33m\u001b[0m\u001b[0m\n\u001b[0;32m     51\u001b[0m     \u001b[0mctx\u001b[0m\u001b[1;33m.\u001b[0m\u001b[0mensure_initialized\u001b[0m\u001b[1;33m(\u001b[0m\u001b[1;33m)\u001b[0m\u001b[1;33m\u001b[0m\u001b[1;33m\u001b[0m\u001b[0m\n\u001b[1;32m---> 52\u001b[1;33m     tensors = pywrap_tfe.TFE_Py_Execute(ctx._handle, device_name, op_name,\n\u001b[0m\u001b[0;32m     53\u001b[0m                                         inputs, attrs, num_outputs)\n\u001b[0;32m     54\u001b[0m   \u001b[1;32mexcept\u001b[0m \u001b[0mcore\u001b[0m\u001b[1;33m.\u001b[0m\u001b[0m_NotOkStatusException\u001b[0m \u001b[1;32mas\u001b[0m \u001b[0me\u001b[0m\u001b[1;33m:\u001b[0m\u001b[1;33m\u001b[0m\u001b[1;33m\u001b[0m\u001b[0m\n",
      "\u001b[1;31mInvalidArgumentError\u001b[0m: Graph execution error:\n\nDetected at node 'model/embedding/embedding_lookup' defined at (most recent call last):\n    File \"C:\\Users\\HP\\anaconda3\\lib\\runpy.py\", line 197, in _run_module_as_main\n      return _run_code(code, main_globals, None,\n    File \"C:\\Users\\HP\\anaconda3\\lib\\runpy.py\", line 87, in _run_code\n      exec(code, run_globals)\n    File \"C:\\Users\\HP\\anaconda3\\lib\\site-packages\\ipykernel_launcher.py\", line 16, in <module>\n      app.launch_new_instance()\n    File \"C:\\Users\\HP\\anaconda3\\lib\\site-packages\\traitlets\\config\\application.py\", line 846, in launch_instance\n      app.start()\n    File \"C:\\Users\\HP\\anaconda3\\lib\\site-packages\\ipykernel\\kernelapp.py\", line 677, in start\n      self.io_loop.start()\n    File \"C:\\Users\\HP\\anaconda3\\lib\\site-packages\\tornado\\platform\\asyncio.py\", line 199, in start\n      self.asyncio_loop.run_forever()\n    File \"C:\\Users\\HP\\anaconda3\\lib\\asyncio\\base_events.py\", line 596, in run_forever\n      self._run_once()\n    File \"C:\\Users\\HP\\anaconda3\\lib\\asyncio\\base_events.py\", line 1890, in _run_once\n      handle._run()\n    File \"C:\\Users\\HP\\anaconda3\\lib\\asyncio\\events.py\", line 80, in _run\n      self._context.run(self._callback, *self._args)\n    File \"C:\\Users\\HP\\anaconda3\\lib\\site-packages\\ipykernel\\kernelbase.py\", line 457, in dispatch_queue\n      await self.process_one()\n    File \"C:\\Users\\HP\\anaconda3\\lib\\site-packages\\ipykernel\\kernelbase.py\", line 446, in process_one\n      await dispatch(*args)\n    File \"C:\\Users\\HP\\anaconda3\\lib\\site-packages\\ipykernel\\kernelbase.py\", line 353, in dispatch_shell\n      await result\n    File \"C:\\Users\\HP\\anaconda3\\lib\\site-packages\\ipykernel\\kernelbase.py\", line 648, in execute_request\n      reply_content = await reply_content\n    File \"C:\\Users\\HP\\anaconda3\\lib\\site-packages\\ipykernel\\ipkernel.py\", line 353, in do_execute\n      res = shell.run_cell(code, store_history=store_history, silent=silent)\n    File \"C:\\Users\\HP\\anaconda3\\lib\\site-packages\\ipykernel\\zmqshell.py\", line 533, in run_cell\n      return super(ZMQInteractiveShell, self).run_cell(*args, **kwargs)\n    File \"C:\\Users\\HP\\anaconda3\\lib\\site-packages\\IPython\\core\\interactiveshell.py\", line 2901, in run_cell\n      result = self._run_cell(\n    File \"C:\\Users\\HP\\anaconda3\\lib\\site-packages\\IPython\\core\\interactiveshell.py\", line 2947, in _run_cell\n      return runner(coro)\n    File \"C:\\Users\\HP\\anaconda3\\lib\\site-packages\\IPython\\core\\async_helpers.py\", line 68, in _pseudo_sync_runner\n      coro.send(None)\n    File \"C:\\Users\\HP\\anaconda3\\lib\\site-packages\\IPython\\core\\interactiveshell.py\", line 3172, in run_cell_async\n      has_raised = await self.run_ast_nodes(code_ast.body, cell_name,\n    File \"C:\\Users\\HP\\anaconda3\\lib\\site-packages\\IPython\\core\\interactiveshell.py\", line 3364, in run_ast_nodes\n      if (await self.run_code(code, result,  async_=asy)):\n    File \"C:\\Users\\HP\\anaconda3\\lib\\site-packages\\IPython\\core\\interactiveshell.py\", line 3444, in run_code\n      exec(code_obj, self.user_global_ns, self.user_ns)\n    File \"C:\\Users\\HP\\AppData\\Local\\Temp/ipykernel_1284/4157008573.py\", line 1, in <module>\n      model.fit([text, question], answers, epochs=10, batch_size=128)\n    File \"C:\\Users\\HP\\anaconda3\\lib\\site-packages\\keras\\utils\\traceback_utils.py\", line 65, in error_handler\n      return fn(*args, **kwargs)\n    File \"C:\\Users\\HP\\anaconda3\\lib\\site-packages\\keras\\engine\\training.py\", line 1685, in fit\n      tmp_logs = self.train_function(iterator)\n    File \"C:\\Users\\HP\\anaconda3\\lib\\site-packages\\keras\\engine\\training.py\", line 1284, in train_function\n      return step_function(self, iterator)\n    File \"C:\\Users\\HP\\anaconda3\\lib\\site-packages\\keras\\engine\\training.py\", line 1268, in step_function\n      outputs = model.distribute_strategy.run(run_step, args=(data,))\n    File \"C:\\Users\\HP\\anaconda3\\lib\\site-packages\\keras\\engine\\training.py\", line 1249, in run_step\n      outputs = model.train_step(data)\n    File \"C:\\Users\\HP\\anaconda3\\lib\\site-packages\\keras\\engine\\training.py\", line 1050, in train_step\n      y_pred = self(x, training=True)\n    File \"C:\\Users\\HP\\anaconda3\\lib\\site-packages\\keras\\utils\\traceback_utils.py\", line 65, in error_handler\n      return fn(*args, **kwargs)\n    File \"C:\\Users\\HP\\anaconda3\\lib\\site-packages\\keras\\engine\\training.py\", line 558, in __call__\n      return super().__call__(*args, **kwargs)\n    File \"C:\\Users\\HP\\anaconda3\\lib\\site-packages\\keras\\utils\\traceback_utils.py\", line 65, in error_handler\n      return fn(*args, **kwargs)\n    File \"C:\\Users\\HP\\anaconda3\\lib\\site-packages\\keras\\engine\\base_layer.py\", line 1145, in __call__\n      outputs = call_fn(inputs, *args, **kwargs)\n    File \"C:\\Users\\HP\\anaconda3\\lib\\site-packages\\keras\\utils\\traceback_utils.py\", line 96, in error_handler\n      return fn(*args, **kwargs)\n    File \"C:\\Users\\HP\\anaconda3\\lib\\site-packages\\keras\\engine\\functional.py\", line 512, in call\n      return self._run_internal_graph(inputs, training=training, mask=mask)\n    File \"C:\\Users\\HP\\anaconda3\\lib\\site-packages\\keras\\engine\\functional.py\", line 669, in _run_internal_graph\n      outputs = node.layer(*args, **kwargs)\n    File \"C:\\Users\\HP\\anaconda3\\lib\\site-packages\\keras\\utils\\traceback_utils.py\", line 65, in error_handler\n      return fn(*args, **kwargs)\n    File \"C:\\Users\\HP\\anaconda3\\lib\\site-packages\\keras\\engine\\base_layer.py\", line 1145, in __call__\n      outputs = call_fn(inputs, *args, **kwargs)\n    File \"C:\\Users\\HP\\anaconda3\\lib\\site-packages\\keras\\utils\\traceback_utils.py\", line 96, in error_handler\n      return fn(*args, **kwargs)\n    File \"C:\\Users\\HP\\anaconda3\\lib\\site-packages\\keras\\layers\\core\\embedding.py\", line 272, in call\n      out = tf.nn.embedding_lookup(self.embeddings, inputs)\nNode: 'model/embedding/embedding_lookup'\nindices[120,0] = 5387 is not in [0, 64)\n\t [[{{node model/embedding/embedding_lookup}}]] [Op:__inference_train_function_5823]"
     ]
    }
   ],
   "source": [
    "model.fit([text, question], answers, epochs=2, batch_size=128)"
   ]
  },
  {
   "cell_type": "code",
   "execution_count": 51,
   "id": "7f91cd8d",
   "metadata": {},
   "outputs": [
    {
     "name": "stdout",
     "output_type": "stream",
     "text": [
      "Epoch 1/10\n"
     ]
    },
    {
     "ename": "InvalidArgumentError",
     "evalue": "Graph execution error:\n\nDetected at node 'model/embedding_1/embedding_lookup' defined at (most recent call last):\n    File \"C:\\Users\\HP\\anaconda3\\lib\\runpy.py\", line 197, in _run_module_as_main\n      return _run_code(code, main_globals, None,\n    File \"C:\\Users\\HP\\anaconda3\\lib\\runpy.py\", line 87, in _run_code\n      exec(code, run_globals)\n    File \"C:\\Users\\HP\\anaconda3\\lib\\site-packages\\ipykernel_launcher.py\", line 16, in <module>\n      app.launch_new_instance()\n    File \"C:\\Users\\HP\\anaconda3\\lib\\site-packages\\traitlets\\config\\application.py\", line 846, in launch_instance\n      app.start()\n    File \"C:\\Users\\HP\\anaconda3\\lib\\site-packages\\ipykernel\\kernelapp.py\", line 677, in start\n      self.io_loop.start()\n    File \"C:\\Users\\HP\\anaconda3\\lib\\site-packages\\tornado\\platform\\asyncio.py\", line 199, in start\n      self.asyncio_loop.run_forever()\n    File \"C:\\Users\\HP\\anaconda3\\lib\\asyncio\\base_events.py\", line 596, in run_forever\n      self._run_once()\n    File \"C:\\Users\\HP\\anaconda3\\lib\\asyncio\\base_events.py\", line 1890, in _run_once\n      handle._run()\n    File \"C:\\Users\\HP\\anaconda3\\lib\\asyncio\\events.py\", line 80, in _run\n      self._context.run(self._callback, *self._args)\n    File \"C:\\Users\\HP\\anaconda3\\lib\\site-packages\\ipykernel\\kernelbase.py\", line 457, in dispatch_queue\n      await self.process_one()\n    File \"C:\\Users\\HP\\anaconda3\\lib\\site-packages\\ipykernel\\kernelbase.py\", line 446, in process_one\n      await dispatch(*args)\n    File \"C:\\Users\\HP\\anaconda3\\lib\\site-packages\\ipykernel\\kernelbase.py\", line 353, in dispatch_shell\n      await result\n    File \"C:\\Users\\HP\\anaconda3\\lib\\site-packages\\ipykernel\\kernelbase.py\", line 648, in execute_request\n      reply_content = await reply_content\n    File \"C:\\Users\\HP\\anaconda3\\lib\\site-packages\\ipykernel\\ipkernel.py\", line 353, in do_execute\n      res = shell.run_cell(code, store_history=store_history, silent=silent)\n    File \"C:\\Users\\HP\\anaconda3\\lib\\site-packages\\ipykernel\\zmqshell.py\", line 533, in run_cell\n      return super(ZMQInteractiveShell, self).run_cell(*args, **kwargs)\n    File \"C:\\Users\\HP\\anaconda3\\lib\\site-packages\\IPython\\core\\interactiveshell.py\", line 2901, in run_cell\n      result = self._run_cell(\n    File \"C:\\Users\\HP\\anaconda3\\lib\\site-packages\\IPython\\core\\interactiveshell.py\", line 2947, in _run_cell\n      return runner(coro)\n    File \"C:\\Users\\HP\\anaconda3\\lib\\site-packages\\IPython\\core\\async_helpers.py\", line 68, in _pseudo_sync_runner\n      coro.send(None)\n    File \"C:\\Users\\HP\\anaconda3\\lib\\site-packages\\IPython\\core\\interactiveshell.py\", line 3172, in run_cell_async\n      has_raised = await self.run_ast_nodes(code_ast.body, cell_name,\n    File \"C:\\Users\\HP\\anaconda3\\lib\\site-packages\\IPython\\core\\interactiveshell.py\", line 3364, in run_ast_nodes\n      if (await self.run_code(code, result,  async_=asy)):\n    File \"C:\\Users\\HP\\anaconda3\\lib\\site-packages\\IPython\\core\\interactiveshell.py\", line 3444, in run_code\n      exec(code_obj, self.user_global_ns, self.user_ns)\n    File \"C:\\Users\\HP\\AppData\\Local\\Temp/ipykernel_1284/607485052.py\", line 1, in <module>\n      model.fit({'text': text, 'question': question}, answers,\n    File \"C:\\Users\\HP\\anaconda3\\lib\\site-packages\\keras\\utils\\traceback_utils.py\", line 65, in error_handler\n      return fn(*args, **kwargs)\n    File \"C:\\Users\\HP\\anaconda3\\lib\\site-packages\\keras\\engine\\training.py\", line 1685, in fit\n      tmp_logs = self.train_function(iterator)\n    File \"C:\\Users\\HP\\anaconda3\\lib\\site-packages\\keras\\engine\\training.py\", line 1284, in train_function\n      return step_function(self, iterator)\n    File \"C:\\Users\\HP\\anaconda3\\lib\\site-packages\\keras\\engine\\training.py\", line 1268, in step_function\n      outputs = model.distribute_strategy.run(run_step, args=(data,))\n    File \"C:\\Users\\HP\\anaconda3\\lib\\site-packages\\keras\\engine\\training.py\", line 1249, in run_step\n      outputs = model.train_step(data)\n    File \"C:\\Users\\HP\\anaconda3\\lib\\site-packages\\keras\\engine\\training.py\", line 1050, in train_step\n      y_pred = self(x, training=True)\n    File \"C:\\Users\\HP\\anaconda3\\lib\\site-packages\\keras\\utils\\traceback_utils.py\", line 65, in error_handler\n      return fn(*args, **kwargs)\n    File \"C:\\Users\\HP\\anaconda3\\lib\\site-packages\\keras\\engine\\training.py\", line 558, in __call__\n      return super().__call__(*args, **kwargs)\n    File \"C:\\Users\\HP\\anaconda3\\lib\\site-packages\\keras\\utils\\traceback_utils.py\", line 65, in error_handler\n      return fn(*args, **kwargs)\n    File \"C:\\Users\\HP\\anaconda3\\lib\\site-packages\\keras\\engine\\base_layer.py\", line 1145, in __call__\n      outputs = call_fn(inputs, *args, **kwargs)\n    File \"C:\\Users\\HP\\anaconda3\\lib\\site-packages\\keras\\utils\\traceback_utils.py\", line 96, in error_handler\n      return fn(*args, **kwargs)\n    File \"C:\\Users\\HP\\anaconda3\\lib\\site-packages\\keras\\engine\\functional.py\", line 512, in call\n      return self._run_internal_graph(inputs, training=training, mask=mask)\n    File \"C:\\Users\\HP\\anaconda3\\lib\\site-packages\\keras\\engine\\functional.py\", line 669, in _run_internal_graph\n      outputs = node.layer(*args, **kwargs)\n    File \"C:\\Users\\HP\\anaconda3\\lib\\site-packages\\keras\\utils\\traceback_utils.py\", line 65, in error_handler\n      return fn(*args, **kwargs)\n    File \"C:\\Users\\HP\\anaconda3\\lib\\site-packages\\keras\\engine\\base_layer.py\", line 1145, in __call__\n      outputs = call_fn(inputs, *args, **kwargs)\n    File \"C:\\Users\\HP\\anaconda3\\lib\\site-packages\\keras\\utils\\traceback_utils.py\", line 96, in error_handler\n      return fn(*args, **kwargs)\n    File \"C:\\Users\\HP\\anaconda3\\lib\\site-packages\\keras\\layers\\core\\embedding.py\", line 272, in call\n      out = tf.nn.embedding_lookup(self.embeddings, inputs)\nNode: 'model/embedding_1/embedding_lookup'\nindices[120,0] = 3807 is not in [0, 32)\n\t [[{{node model/embedding_1/embedding_lookup}}]] [Op:__inference_train_function_8442]",
     "output_type": "error",
     "traceback": [
      "\u001b[1;31m---------------------------------------------------------------------------\u001b[0m",
      "\u001b[1;31mInvalidArgumentError\u001b[0m                      Traceback (most recent call last)",
      "\u001b[1;32m~\\AppData\\Local\\Temp/ipykernel_1284/607485052.py\u001b[0m in \u001b[0;36m<module>\u001b[1;34m\u001b[0m\n\u001b[1;32m----> 1\u001b[1;33m model.fit({'text': text, 'question': question}, answers,\n\u001b[0m\u001b[0;32m      2\u001b[0m  epochs=10, batch_size=128)\n",
      "\u001b[1;32m~\\anaconda3\\lib\\site-packages\\keras\\utils\\traceback_utils.py\u001b[0m in \u001b[0;36merror_handler\u001b[1;34m(*args, **kwargs)\u001b[0m\n\u001b[0;32m     68\u001b[0m             \u001b[1;31m# To get the full stack trace, call:\u001b[0m\u001b[1;33m\u001b[0m\u001b[1;33m\u001b[0m\u001b[0m\n\u001b[0;32m     69\u001b[0m             \u001b[1;31m# `tf.debugging.disable_traceback_filtering()`\u001b[0m\u001b[1;33m\u001b[0m\u001b[1;33m\u001b[0m\u001b[0m\n\u001b[1;32m---> 70\u001b[1;33m             \u001b[1;32mraise\u001b[0m \u001b[0me\u001b[0m\u001b[1;33m.\u001b[0m\u001b[0mwith_traceback\u001b[0m\u001b[1;33m(\u001b[0m\u001b[0mfiltered_tb\u001b[0m\u001b[1;33m)\u001b[0m \u001b[1;32mfrom\u001b[0m \u001b[1;32mNone\u001b[0m\u001b[1;33m\u001b[0m\u001b[1;33m\u001b[0m\u001b[0m\n\u001b[0m\u001b[0;32m     71\u001b[0m         \u001b[1;32mfinally\u001b[0m\u001b[1;33m:\u001b[0m\u001b[1;33m\u001b[0m\u001b[1;33m\u001b[0m\u001b[0m\n\u001b[0;32m     72\u001b[0m             \u001b[1;32mdel\u001b[0m \u001b[0mfiltered_tb\u001b[0m\u001b[1;33m\u001b[0m\u001b[1;33m\u001b[0m\u001b[0m\n",
      "\u001b[1;32m~\\anaconda3\\lib\\site-packages\\tensorflow\\python\\eager\\execute.py\u001b[0m in \u001b[0;36mquick_execute\u001b[1;34m(op_name, num_outputs, inputs, attrs, ctx, name)\u001b[0m\n\u001b[0;32m     50\u001b[0m   \u001b[1;32mtry\u001b[0m\u001b[1;33m:\u001b[0m\u001b[1;33m\u001b[0m\u001b[1;33m\u001b[0m\u001b[0m\n\u001b[0;32m     51\u001b[0m     \u001b[0mctx\u001b[0m\u001b[1;33m.\u001b[0m\u001b[0mensure_initialized\u001b[0m\u001b[1;33m(\u001b[0m\u001b[1;33m)\u001b[0m\u001b[1;33m\u001b[0m\u001b[1;33m\u001b[0m\u001b[0m\n\u001b[1;32m---> 52\u001b[1;33m     tensors = pywrap_tfe.TFE_Py_Execute(ctx._handle, device_name, op_name,\n\u001b[0m\u001b[0;32m     53\u001b[0m                                         inputs, attrs, num_outputs)\n\u001b[0;32m     54\u001b[0m   \u001b[1;32mexcept\u001b[0m \u001b[0mcore\u001b[0m\u001b[1;33m.\u001b[0m\u001b[0m_NotOkStatusException\u001b[0m \u001b[1;32mas\u001b[0m \u001b[0me\u001b[0m\u001b[1;33m:\u001b[0m\u001b[1;33m\u001b[0m\u001b[1;33m\u001b[0m\u001b[0m\n",
      "\u001b[1;31mInvalidArgumentError\u001b[0m: Graph execution error:\n\nDetected at node 'model/embedding_1/embedding_lookup' defined at (most recent call last):\n    File \"C:\\Users\\HP\\anaconda3\\lib\\runpy.py\", line 197, in _run_module_as_main\n      return _run_code(code, main_globals, None,\n    File \"C:\\Users\\HP\\anaconda3\\lib\\runpy.py\", line 87, in _run_code\n      exec(code, run_globals)\n    File \"C:\\Users\\HP\\anaconda3\\lib\\site-packages\\ipykernel_launcher.py\", line 16, in <module>\n      app.launch_new_instance()\n    File \"C:\\Users\\HP\\anaconda3\\lib\\site-packages\\traitlets\\config\\application.py\", line 846, in launch_instance\n      app.start()\n    File \"C:\\Users\\HP\\anaconda3\\lib\\site-packages\\ipykernel\\kernelapp.py\", line 677, in start\n      self.io_loop.start()\n    File \"C:\\Users\\HP\\anaconda3\\lib\\site-packages\\tornado\\platform\\asyncio.py\", line 199, in start\n      self.asyncio_loop.run_forever()\n    File \"C:\\Users\\HP\\anaconda3\\lib\\asyncio\\base_events.py\", line 596, in run_forever\n      self._run_once()\n    File \"C:\\Users\\HP\\anaconda3\\lib\\asyncio\\base_events.py\", line 1890, in _run_once\n      handle._run()\n    File \"C:\\Users\\HP\\anaconda3\\lib\\asyncio\\events.py\", line 80, in _run\n      self._context.run(self._callback, *self._args)\n    File \"C:\\Users\\HP\\anaconda3\\lib\\site-packages\\ipykernel\\kernelbase.py\", line 457, in dispatch_queue\n      await self.process_one()\n    File \"C:\\Users\\HP\\anaconda3\\lib\\site-packages\\ipykernel\\kernelbase.py\", line 446, in process_one\n      await dispatch(*args)\n    File \"C:\\Users\\HP\\anaconda3\\lib\\site-packages\\ipykernel\\kernelbase.py\", line 353, in dispatch_shell\n      await result\n    File \"C:\\Users\\HP\\anaconda3\\lib\\site-packages\\ipykernel\\kernelbase.py\", line 648, in execute_request\n      reply_content = await reply_content\n    File \"C:\\Users\\HP\\anaconda3\\lib\\site-packages\\ipykernel\\ipkernel.py\", line 353, in do_execute\n      res = shell.run_cell(code, store_history=store_history, silent=silent)\n    File \"C:\\Users\\HP\\anaconda3\\lib\\site-packages\\ipykernel\\zmqshell.py\", line 533, in run_cell\n      return super(ZMQInteractiveShell, self).run_cell(*args, **kwargs)\n    File \"C:\\Users\\HP\\anaconda3\\lib\\site-packages\\IPython\\core\\interactiveshell.py\", line 2901, in run_cell\n      result = self._run_cell(\n    File \"C:\\Users\\HP\\anaconda3\\lib\\site-packages\\IPython\\core\\interactiveshell.py\", line 2947, in _run_cell\n      return runner(coro)\n    File \"C:\\Users\\HP\\anaconda3\\lib\\site-packages\\IPython\\core\\async_helpers.py\", line 68, in _pseudo_sync_runner\n      coro.send(None)\n    File \"C:\\Users\\HP\\anaconda3\\lib\\site-packages\\IPython\\core\\interactiveshell.py\", line 3172, in run_cell_async\n      has_raised = await self.run_ast_nodes(code_ast.body, cell_name,\n    File \"C:\\Users\\HP\\anaconda3\\lib\\site-packages\\IPython\\core\\interactiveshell.py\", line 3364, in run_ast_nodes\n      if (await self.run_code(code, result,  async_=asy)):\n    File \"C:\\Users\\HP\\anaconda3\\lib\\site-packages\\IPython\\core\\interactiveshell.py\", line 3444, in run_code\n      exec(code_obj, self.user_global_ns, self.user_ns)\n    File \"C:\\Users\\HP\\AppData\\Local\\Temp/ipykernel_1284/607485052.py\", line 1, in <module>\n      model.fit({'text': text, 'question': question}, answers,\n    File \"C:\\Users\\HP\\anaconda3\\lib\\site-packages\\keras\\utils\\traceback_utils.py\", line 65, in error_handler\n      return fn(*args, **kwargs)\n    File \"C:\\Users\\HP\\anaconda3\\lib\\site-packages\\keras\\engine\\training.py\", line 1685, in fit\n      tmp_logs = self.train_function(iterator)\n    File \"C:\\Users\\HP\\anaconda3\\lib\\site-packages\\keras\\engine\\training.py\", line 1284, in train_function\n      return step_function(self, iterator)\n    File \"C:\\Users\\HP\\anaconda3\\lib\\site-packages\\keras\\engine\\training.py\", line 1268, in step_function\n      outputs = model.distribute_strategy.run(run_step, args=(data,))\n    File \"C:\\Users\\HP\\anaconda3\\lib\\site-packages\\keras\\engine\\training.py\", line 1249, in run_step\n      outputs = model.train_step(data)\n    File \"C:\\Users\\HP\\anaconda3\\lib\\site-packages\\keras\\engine\\training.py\", line 1050, in train_step\n      y_pred = self(x, training=True)\n    File \"C:\\Users\\HP\\anaconda3\\lib\\site-packages\\keras\\utils\\traceback_utils.py\", line 65, in error_handler\n      return fn(*args, **kwargs)\n    File \"C:\\Users\\HP\\anaconda3\\lib\\site-packages\\keras\\engine\\training.py\", line 558, in __call__\n      return super().__call__(*args, **kwargs)\n    File \"C:\\Users\\HP\\anaconda3\\lib\\site-packages\\keras\\utils\\traceback_utils.py\", line 65, in error_handler\n      return fn(*args, **kwargs)\n    File \"C:\\Users\\HP\\anaconda3\\lib\\site-packages\\keras\\engine\\base_layer.py\", line 1145, in __call__\n      outputs = call_fn(inputs, *args, **kwargs)\n    File \"C:\\Users\\HP\\anaconda3\\lib\\site-packages\\keras\\utils\\traceback_utils.py\", line 96, in error_handler\n      return fn(*args, **kwargs)\n    File \"C:\\Users\\HP\\anaconda3\\lib\\site-packages\\keras\\engine\\functional.py\", line 512, in call\n      return self._run_internal_graph(inputs, training=training, mask=mask)\n    File \"C:\\Users\\HP\\anaconda3\\lib\\site-packages\\keras\\engine\\functional.py\", line 669, in _run_internal_graph\n      outputs = node.layer(*args, **kwargs)\n    File \"C:\\Users\\HP\\anaconda3\\lib\\site-packages\\keras\\utils\\traceback_utils.py\", line 65, in error_handler\n      return fn(*args, **kwargs)\n    File \"C:\\Users\\HP\\anaconda3\\lib\\site-packages\\keras\\engine\\base_layer.py\", line 1145, in __call__\n      outputs = call_fn(inputs, *args, **kwargs)\n    File \"C:\\Users\\HP\\anaconda3\\lib\\site-packages\\keras\\utils\\traceback_utils.py\", line 96, in error_handler\n      return fn(*args, **kwargs)\n    File \"C:\\Users\\HP\\anaconda3\\lib\\site-packages\\keras\\layers\\core\\embedding.py\", line 272, in call\n      out = tf.nn.embedding_lookup(self.embeddings, inputs)\nNode: 'model/embedding_1/embedding_lookup'\nindices[120,0] = 3807 is not in [0, 32)\n\t [[{{node model/embedding_1/embedding_lookup}}]] [Op:__inference_train_function_8442]"
     ]
    }
   ],
   "source": [
    "model.fit({'text': text, 'question': question}, answers,\n",
    " epochs=10, batch_size=128)"
   ]
  },
  {
   "cell_type": "markdown",
   "id": "d5072218",
   "metadata": {},
   "source": [
    "## Listing 7.3 Functional API implementation of a three-output model"
   ]
  },
  {
   "cell_type": "code",
   "execution_count": 52,
   "id": "c22447c4",
   "metadata": {},
   "outputs": [],
   "source": [
    "from keras import layers\n",
    "from keras import Input\n",
    "from keras.models import Model\n",
    "vocabulary_size = 50000\n",
    "num_income_groups = 10\n",
    "posts_input = Input(shape=(None,), dtype='int32', name='posts')\n",
    "embedded_posts = layers.Embedding(256, vocabulary_size)(posts_input)\n",
    "x = layers.Conv1D(128, 5, activation='relu')(embedded_posts)\n",
    "x = layers.MaxPooling1D(5)(x)\n",
    "x = layers.Conv1D(256, 5, activation='relu')(x)\n",
    "x = layers.Conv1D(256, 5, activation='relu')(x)\n",
    "x = layers.MaxPooling1D(5)(x)\n",
    "x = layers.Conv1D(256, 5, activation='relu')(x)\n",
    "x = layers.Conv1D(256, 5, activation='relu')(x)\n",
    "x = layers.GlobalMaxPooling1D()(x)\n",
    "x = layers.Dense(128, activation='relu')(x)\n",
    "age_prediction = layers.Dense(1, name='age')(x)\n",
    "income_prediction = layers.Dense(num_income_groups,\n",
    "activation='softmax',\n",
    "name='income')(x)\n",
    "gender_prediction = layers.Dense(1, activation='sigmoid', name='gender')(x)\n",
    "model = Model(posts_input,\n",
    "[age_prediction, income_prediction, gender_prediction])"
   ]
  }
 ],
 "metadata": {
  "kernelspec": {
   "display_name": "Python 3 (ipykernel)",
   "language": "python",
   "name": "python3"
  },
  "language_info": {
   "codemirror_mode": {
    "name": "ipython",
    "version": 3
   },
   "file_extension": ".py",
   "mimetype": "text/x-python",
   "name": "python",
   "nbconvert_exporter": "python",
   "pygments_lexer": "ipython3",
   "version": "3.9.7"
  }
 },
 "nbformat": 4,
 "nbformat_minor": 5
}
